<?xml version="1.0" encoding="utf-8"?>
<!-- This URDF was automatically created by SolidWorks to URDF Exporter! Originally created by Stephen Brawner (brawner@gmail.com) 
     Commit Version: 1.5.1-0-g916b5db  Build Version: 1.5.7152.31018
     For more information, please see http://wiki.ros.org/sw_urdf_exporter -->
<!--<xacro:property name="pi" value="3.1415926535898" />-->
<robot name="robot" xmlns:xacro="http://www.ros.org/wiki/xacro">
  <gazebo>
    <static>false</static>
    <plugin filename="libgazebo_ros_control.so" name="gazebo_ros_control">
      <robotNamespace>/robot</robotNamespace>
      <robotSimType>gazebo_ros_control/DefaultRobotHWSim</robotSimType>
      <legacyModeNS>true</legacyModeNS>
    </plugin>
  </gazebo>

  <!--<gazebo reference="world">
  </gazebo>-->

  <gazebo reference="robot">
    <kp>1000000.0</kp>
    <kd>1.0</kd>
    <mu1>1.0</mu1>
    <mu2>1.0</mu2>
    <minDepth>0.001</minDepth>
    <kinematic>1</kinematic>
    <material>Gazebo/Black</material>
  </gazebo>

  <gazebo reference="link_head">
    <kp>1000000.0</kp>
    <kd>1.0</kd>
    <mu1>1.0</mu1>
    <mu2>1.0</mu2>
    <minDepth>0.001</minDepth>
    <material>Gazebo/Black</material>
  </gazebo>

  <gazebo reference="link_camera">
    <kp>1000000.0</kp>
    <kd>1.0</kd>
    <mu1>1.0</mu1>
    <mu2>1.0</mu2>
    <minDepth>0.001</minDepth>
    <material>Gazebo/SkyBlue</material>
  </gazebo>

  <gazebo reference="link_right_arm">
    <kp>1000000.0</kp>
    <kd>1.0</kd>
    <mu1>1.0</mu1>
    <mu2>1.0</mu2>
    <minDepth>0.001</minDepth>
    <material>Gazebo/Blue</material>
  </gazebo>

  <gazebo reference="link_right_elbow">
    <kp>1000000.0</kp>
    <kd>1.0</kd>
    <mu1>1.0</mu1>
    <mu2>1.0</mu2>
    <minDepth>0.001</minDepth>
    <material>Gazebo/Black</material>
  </gazebo>

  <gazebo reference="link_left_arm">
    <kp>1000000.0</kp>
    <kd>1.0</kd>
    <mu1>1.0</mu1>
    <mu2>1.0</mu2>
    <minDepth>0.001</minDepth>
    <material>Gazebo/Blue</material>
  </gazebo>

  <gazebo reference="link_left_elbow">
    <kp>1000000.0</kp>
    <kd>1.0</kd>
    <mu1>1.0</mu1>
    <mu2>1.0</mu2>
    <minDepth>0.001</minDepth>
    <material>Gazebo/Black</material>
  </gazebo>

  <gazebo reference="link_right_leg">
    <kp>1000000.0</kp>
    <kd>1.0</kd>
    <mu1>1.0</mu1>
    <mu2>1.0</mu2>
    <minDepth>0.001</minDepth>
  </gazebo>

  <gazebo reference="link_right_leg1">
    <kp>1000000.0</kp>
    <kd>1.0</kd>
    <mu1>1.0</mu1>
    <mu2>1.0</mu2>
    <minDepth>0.001</minDepth>
  </gazebo>

  <gazebo reference="link_right_leg2">
    <kp>1000000.0</kp>
    <kd>1.0</kd>
    <mu1>1.0</mu1>
    <mu2>1.0</mu2>
    <minDepth>0.001</minDepth>
  </gazebo>

  <gazebo reference="link_right_leg3">
    <kp>1000000.0</kp>
    <kd>1.0</kd>
    <mu1>1.0</mu1>
    <mu2>1.0</mu2>
    <minDepth>0.001</minDepth>
  </gazebo>

  <gazebo reference="link_right_leg4">
    <kp>1000000.0</kp>
    <kd>1.0</kd>
    <mu1>1.0</mu1>
    <mu2>1.0</mu2>
    <minDepth>0.001</minDepth>
  </gazebo>

  <gazebo reference="link_right_leg5">
    <kp>1000000.0</kp>
    <kd>1.0</kd>
    <mu1>1.0</mu1>
    <mu2>1.0</mu2>
    <minDepth>0.001</minDepth>
  </gazebo>

  <gazebo reference="link_left_leg">
    <kp>1000000.0</kp>
    <kd>1.0</kd>
    <mu1>1.0</mu1>
    <mu2>1.0</mu2>
    <minDepth>0.001</minDepth>
  </gazebo>

  <gazebo reference="link_left_leg1">
    <kp>1000000.0</kp>
    <kd>1.0</kd>
    <mu1>1.0</mu1>
    <mu2>1.0</mu2>
    <minDepth>0.001</minDepth>
  </gazebo>

  <gazebo reference="link_left_leg2">
    <kp>1000000.0</kp>
    <kd>1.0</kd>
    <mu1>1.0</mu1>
    <mu2>1.0</mu2>
    <minDepth>0.001</minDepth>
  </gazebo>

  <gazebo reference="link_left_leg3">
    <kp>1000000.0</kp>
    <kd>1.0</kd>
    <mu1>1.0</mu1>
    <mu2>1.0</mu2>
    <minDepth>0.001</minDepth>
  </gazebo>

  <gazebo reference="link_left_leg4">
    <kp>1000000.0</kp>
    <kd>1.0</kd>
    <mu1>1.0</mu1>
    <mu2>1.0</mu2>
    <minDepth>0.001</minDepth>
  </gazebo>

  <gazebo reference="link_left_leg5">
    <kp>1000000.0</kp>
    <kd>1.0</kd>
    <mu1>1.0</mu1>
    <mu2>1.0</mu2>
    <minDepth>0.001</minDepth>
  </gazebo>


  <gazebo reference="link_right_feet">
    <kp>1000000.0</kp>
    <kd>1.0</kd>
    <mu1>1.0</mu1>
    <mu2>1.0</mu2>
    <minDepth>0.001</minDepth>
    <material>Gazebo/Black</material>
  </gazebo>

  <gazebo reference="link_left_feet">
    <kp>1000000.0</kp>
    <kd>1.0</kd>
    <mu1>1.0</mu1>
    <mu2>1.0</mu2>
    <minDepth>0.001</minDepth>
    <material>Gazebo/Black</material>
  </gazebo>

  <!--<link name="world"/>

  <joint name="joint_world" type="planar">
    <parent link="world"/>
    <child link="robot"/>-->
    <!--<axis
      xyz="0 0 1" />-->
  <!--</joint>-->

  <link
    name="robot">
    <inertial>
      <origin
        xyz="0.125427806910475 -0.0476759257391143 0.452917940277256"
        rpy="0 0 0" />
      <mass
        value="1.21806144630376" />
      <inertia
        ixx="0.000901948633433237"
        ixy="4.34347409154821E-06"
        ixz="-1.5136138375863E-06"
        iyy="0.00114184246607182"
        iyz="1.94125424553875E-05"
        izz="0.000928310082733342" />
    </inertial>
    <visual>
      <origin
        xyz="0.110 0.095 0.3705"
        rpy="0 0 0" />
      <geometry>
        <mesh
          filename="/meshes/body.STL" />
      </geometry>
      <material
        name="white">
        <color
          rgba="0.92941 0.92941 0.92941 1" />
      </material>
    </visual>
    <collision>
      <origin
        xyz="0.110 0.095 0.3705"
        rpy="0 0 0" />
      <geometry>
        <mesh
          filename="/meshes/body.STL" />
      </geometry>
    </collision>
  </link>
  <link
    name="link_head">
    <inertial>
      <origin
        xyz="-0.0224626560785777 0.00562950581166588 0.000186917726442751"
        rpy="0 0 0" />
      <mass
        value="0.0099162446914857" />
      <inertia
        ixx="1.06310866557229E-06"
        ixy="8.61043242646561E-21"
        ixz="-2.27474668452083E-21"
        iyy="3.64347957354398E-06"
        iyz="-5.93004305296224E-21"
        izz="3.84184669937108E-06" />
    </inertial>
    <visual>
      <origin
        xyz="0 0 0"
        rpy="0 0 0" />
      <geometry>
        <mesh
          filename="/meshes/link_head.STL" />
      </geometry>
      <material
        name="darkgray">
        <color
          rgba="0.59216 0.61691 0.65098 1" />
      </material>
    </visual>
    <collision>
      <origin
        xyz="0 0 0"
        rpy="0 0 0" />
      <geometry>
        <mesh
          filename="/meshes/link_head.STL" />
      </geometry>
    </collision>
  </link>
  <joint
    name="joint_head"
    type="revolute">
    <origin
      xyz="0.12518 -0.026245 0.55467"
      rpy="1.5707963267949 0 0" />
    <parent
      link="robot" />
    <child
      link="link_head" />
    <axis
      xyz="0 1 0" />
    <limit
      lower="-0.7854"
      upper="0.7854"
      effort="0"
      velocity="0.5" />
  </joint>
  <link
    name="link_camera">
    <inertial>
      <origin
        xyz="0.0211008609138299 -0.0187255950306598 -0.0173831456927626"
        rpy="0 0 0" />
      <mass
        value="0.132937426451462" />
      <inertia
        ixx="3.82057425486415E-05"
        ixy="-6.5557188658328E-13"
        ixz="3.10661005331095E-07"
        iyy="2.82483798873143E-05"
        iyz="3.04301943557444E-07"
        izz="3.43881587564619E-05" />
    </inertial>
    <visual>
      <origin
        xyz="0 0 0"
        rpy="0 0 0" />
      <geometry>
        <mesh
          filename="/meshes/link_camera.STL" />
      </geometry>
      <material
        name="gray">
        <color
          rgba="0.69804 0.69804 0.69804 1" />
      </material>
    </visual>
    <collision>
      <origin
        xyz="0 0 0"
        rpy="0 0 0" />
      <geometry>
        <mesh
          filename="/meshes/link_camera.STL" />
      </geometry>
    </collision>
  </link>
  <joint
    name="joint_camera"
    type="revolute">
    <origin
      xyz="-0.021049 0.020023 0.00097954"
      rpy="0 0 0" />
    <parent
      link="link_head" />
    <child
      link="link_camera" />
    <axis
      xyz="-1 0 0" />
    <limit
      lower="-0.7854"
      upper="0.7854"
      effort="0"
      velocity="0.5" />
  </joint>

  <link
    name="link_sensor">
    <inertial>
      <origin
        xyz="0 0 0"
        rpy="0 0 0" />
      <mass
        value="0.0000009515105335" />
      <inertia
        ixx="1E-30"
        ixy="1E-30"
        ixz="1E-30"
        iyy="1E-30"
        iyz="1E-30"
        izz="1E-30" />
    </inertial>
    <visual>
      <origin
        xyz="0 0 0"
        rpy="0 1.5707963267949 0" />
      <geometry>
        <box size="0.01 0.01 0.01"/>       
      </geometry>
      <material
        name="gray">
        <color
          rgba="0.69804 0.69804 0.69804 1" />
      </material>
    </visual>
    <collision>
      <origin
        xyz="0 0 0"
        rpy="0 0 0" />
      <geometry>
        <box size="0.01 0.01 0.01"/>            
      </geometry>
    </collision>
  </link>

  <joint
    name="joint_sensor"
    type="fixed">
    <origin
      xyz="0.021 0.065 -0.006"
      rpy="0 1.5707963267949 1.5707963267949" />
    <parent
      link="link_camera" />
    <child
      link="link_sensor" />
    <axis
      xyz="1 0 0" />
    <limit
      lower="0"
      upper="0"
      effort="0.0"
      velocity="0.5" />
  </joint>

  <gazebo reference="link_sensor"> 
    <sensor type="depth" name="camera">
      <update_rate>30.0</update_rate>
      <camera name="camera">
        <horizontal_fov>1.3962634</horizontal_fov>
        <image>
          <width>640</width>
          <height>480</height>
          <format>R8G8B8</format>
        </image>
        <clip>
          <near>0.02</near>
          <far>300</far>
        </clip>
      </camera>

      <plugin name="kinect_camera_controller" filename="libgazebo_ros_openni_kinect.so">
        <alwaysOn>true</alwaysOn>
        <updateRate>30</updateRate>
        <cameraName>camera</cameraName>
        <imageTopicName>rgb/image_raw</imageTopicName>
        <depthImageTopicName>depth_registered/image_raw</depthImageTopicName>
	<pointCloudTopicName>depth/points</pointCloudTopicName>
        <cameraInfoTopicName>rgb/camera_info</cameraInfoTopicName>
	<depthImageCameraInfoTopicName>depth/camera_info</depthImageCameraInfoTopicName>
        <frameName>camera_depth_optical_frame</frameName>
        <!--<frameName>world</frameName>-->
        <baseline>0.1</baseline>
	<distortion_k1>0.0</distortion_k1>
	<distortion_k2>0.0</distortion_k2>
	<distortion_k3>0.0</distortion_k3>
	<distortion_t1>0.0</distortion_t1>
        <distortion_t2>0.0</distortion_t2>
        <pointCloudCutoff>0.4</pointCloudCutoff>
      </plugin>
    </sensor>
  </gazebo>

  <link
    name="link_right_arm">
    <inertial>
      <origin
        xyz="0.069123573730931 -0.0881245279235295 -0.000302414430741513"
        rpy="0 0 0" />
      <mass
        value="0.162855702403727" />
      <inertia
        ixx="9.5745078159835E-05"
        ixy="8.15477830140126E-06"
        ixz="-1.10383512895627E-10"
        iyy="5.08364988621305E-05"
        iyz="2.89059930395425E-11"
        izz="9.40096280886324E-05" />
    </inertial>
    <visual>
      <origin
        xyz="-0.067 -0.0042 0"
        rpy="0 0 0" />
      <geometry>
        <mesh
          filename="/meshes/link_right_arm.STL" />
      </geometry>
      <material
        name="darkgray">
        <color
          rgba="0.59216 0.61691 0.65098 1" />
      </material>
    </visual>
    <collision>
      <origin
        xyz="-0.067 -0.0042 0"
        rpy="0 0 0" />
      <geometry>
        <mesh
          filename="/meshes/link_right_arm.STL" />
      </geometry>
    </collision>
  </link>
  <joint
    name="joint_right_arm"
    type="revolute">
    <origin
      xyz="0.22821 -0.0346 0.5382"
      rpy="1.5707963267949 0 0" />
    <parent
      link="robot" />
    <child
      link="link_right_arm" />
    <axis
      xyz="-1 0 0" />
    <limit
      lower="-3.1415926535898"
      upper="3.1415926535898"
      effort="0"
      velocity="0.5" />
  </joint>
  <link
    name="link_right_elbow">
    <inertial>
      <origin
        xyz="0.0612856493303112 -0.047000000000004 -3.56659146660832E-15"
        rpy="0 0 0" />
      <mass
        value="0.0254627620254795" />
      <inertia
        ixx="1.92462347352125E-06"
        ixy="1.96473583178598E-21"
        ixz="3.91431015245941E-20"
        iyy="6.27178954963994E-05"
        iyz="1.12024781458537E-20"
        izz="6.08314661659164E-05" />
    </inertial>
    <visual>
      <origin
        xyz="0.004 -0.0042 0"
        rpy="0 0 0" />
      <geometry>
        <mesh
          filename="/meshes/link_right_elbow.STL" />
      </geometry>
      <material
        name="white">
        <color
          rgba="0.92941 0.92941 0.92941 1" />
      </material>
    </visual>
    <collision>
      <origin
        xyz="0.004 -0.0042 0"
        rpy="0 0 0" />
      <geometry>
        <mesh
          filename="/meshes/link_right_elbow.STL" />
      </geometry>
    </collision>
  </link>
  <joint
    name="joint_right_elbow"
    type="revolute">
    <origin
      xyz="-0.001045355098888 -0.121 -0.0004"
      rpy="0 0 0" />
    <parent
      link="link_right_arm" />
    <child
      link="link_right_elbow" />
    <axis
      xyz="1 0 0" />
    <limit
      lower="-3.1415926535898"
      upper="3.1415926535898"
      effort="0"
      velocity="0.5" />
  </joint>
  <link
    name="link_left_arm">
    <inertial>
      <origin
        xyz="-0.0199268063679618 -0.0881245279235296 -0.00030241443073447"
        rpy="0 0 0" />
      <mass
        value="0.162855702403727" />
      <inertia
        ixx="9.57450781598346E-05"
        ixy="8.15477830140113E-06"
        ixz="-1.10383512837493E-10"
        iyy="5.08364988621304E-05"
        iyz="2.89059929126298E-11"
        izz="9.4009628088632E-05" />
    </inertial>
    <visual>
      <origin
        xyz="0.067 -0.0042 0"
        rpy="0 3.1415926535898 0" />
      <geometry>
        <mesh
          filename="/meshes/link_left_arm.STL" />
      </geometry>
      <material
        name="darkgray">
        <color
          rgba="0.59216 0.61961 0.65098 1" />
      </material>
    </visual>
    <collision>
      <origin
        xyz="0.067 -0.0042 0"
        rpy="0 3.1415926535898 0" />
      <geometry>
        <mesh
          filename="/meshes/link_left_arm.STL" />
      </geometry>
    </collision>
  </link>
  <joint
    name="joint_left_arm"
    type="revolute">
    <origin
      xyz="0.021579 -0.0346 0.5382"
      rpy="1.5707963267949 0 0" />
    <parent
      link="robot" />
    <child
      link="link_left_arm" />
    <axis
      xyz="-1 0 0" />
    <limit
      lower="-3.1415926535898"
      upper="3.1415926535898"
      effort="0"
      velocity="0.5" />
  </joint>
  <link
    name="link_left_elbow">
    <inertial>
      <origin
        xyz="0.0612856493303112 -0.00599497499999903 3.92741394961149E-15"
        rpy="0 0 0" />
      <mass
        value="0.0254627620254794" />
      <inertia
        ixx="1.92462347352125E-06"
        ixy="1.52001879315177E-19"
        ixz="-8.07957385512967E-20"
        iyy="6.27178954963994E-05"
        iyz="8.16880141462072E-22"
        izz="6.08314661659163E-05" />
    </inertial>
    <visual>
      <origin
        xyz="-0.004 -0.0042 0"
        rpy="0 0 0" />
      <geometry>
        <mesh
          filename="/meshes/link_left_elbow.STL" />
      </geometry>
      <material
        name="white">
        <color
          rgba="0.92941 0.92941 0.92941 1" />
      </material>
    </visual>
    <collision>
      <origin
        xyz="-0.004 -0.0042 0"
        rpy="0 0 0" />
      <geometry>
        <mesh
          filename="/meshes/link_left_elbow.STL" />
      </geometry>
    </collision>
  </link>
  <joint
    name="joint_left_elbow"
    type="revolute">
    <origin
      xyz="-0.0480453550988878 -0.121 0.000399999999999026"
      rpy="0 0 0" />
    <parent
      link="link_left_arm" />
    <child
      link="link_left_elbow" />
    <axis
      xyz="-1 0 0" />
    <limit
      lower="-3.1415926535898"
      upper="3.1415926535898"
      effort="0"
      velocity="0.5" />
  </joint>
  <link
    name="link_right_leg">
    <inertial>
      <origin
        xyz="-0.0201161082476755 0.0019667603442608 0.0679353577417088"
        rpy="0 0 0" />
      <mass
        value="0.189398368135878" />
      <inertia
        ixx="7.40475732087511E-05"
        ixy="-3.92920161170625E-09"
        ixz="-1.80590606727015E-06"
        iyy="7.87337679439145E-05"
        iyz="3.76200105960215E-08"
        izz="5.73837775182643E-05" />
    </inertial>
    <visual>
      <origin
        xyz="-0.18 -0.395 -0.035"
        rpy="-1.5707963267949 0 0" />
      <geometry>
        <mesh
          filename="/meshes/link_right_leg.STL" />
      </geometry>
      <material
        name="darkgray">
        <color
          rgba="0.59216 0.61691 0.65098 1" />
      </material>
    </visual>
    <collision>
      <origin
        xyz="-0.18 -0.395 -0.035"
        rpy="-1.5707963267949 0 0" />
      <geometry>
        <mesh
          filename="/meshes/link_right_leg.STL" />
      </geometry>
    </collision>
  </link>
  <joint
    name="joint_right_leg"
    type="revolute">
    <origin
      xyz="0.18011 -0.0346 0.3943"
      rpy="1.5707963267949 0 0" />
    <parent
      link="robot" />
    <child
      link="link_right_leg" />
    <axis
      xyz="0 1 0" />
    <limit
      lower="-0.0873"
      upper="0.0873"
      effort="0"
      velocity="0.5" />
  </joint>
  <link
    name="link_right_leg1">
    <inertial>
      <origin
        xyz="-0.0201001030678568 -0.0164004141656287 0.00260496657402377"
        rpy="0 0 0" />
      <mass
        value="0.134775732173006" />
      <inertia
        ixx="5.19579790757104E-05"
        ixy="-6.80480393273162E-13"
        ixz="2.89499673761289E-14"
        iyy="2.9276561310441E-05"
        iyz="-1.49805771284268E-06"
        izz="4.32142876668394E-05" />
    </inertial>
    <visual>
      <origin
        xyz="0.025 -0.01 -0.017"
        rpy="1.5707963267949 3.1415926535898 0" />
      <geometry>
        <mesh
          filename="/meshes/link_right_leg1.STL" />
      </geometry>
      <material
        name="gray">
        <color
          rgba="0.69804 0.69804 0.69804 1" />
      </material>
    </visual>
    <collision>
      <origin
        xyz="0.025 -0.01 -0.017"
        rpy="1.5707963267949 3.1415926535898 0" />
      <geometry>
        <mesh
          filename="/meshes/link_right_leg1.STL" />
      </geometry>
    </collision>
  </link>
  <joint
    name="joint_right_leg1"
    type="revolute">
    <origin
      xyz="0 -0.0584999999999977 0.0500000000000002"
      rpy="0 0 0" />
    <parent
      link="link_right_leg" />
    <child
      link="link_right_leg1" />
    <axis
      xyz="0 0 -1" />
    <limit
      lower="-0.436"
      upper="0.110"
      effort="0"
      velocity="0.5" />
  </joint>
  <link
    name="link_right_leg2">
    <inertial>
      <origin
        xyz="0.00716113241659487 -0.101913809829755 0.0201059895820769"
        rpy="0 0 0" />
      <mass
        value="0.190813095388896" />
      <inertia
        ixx="0.000108331753900892"
        ixy="-2.79257127373919E-09"
        ixz="-3.9292016115476E-09"
        iyy="4.21436661659492E-05"
        iyz="1.80590606727017E-06"
        izz="9.63817945941756E-05" />
    </inertial>
    <visual>
      <origin
        xyz="0 0 0"
        rpy="0 0 0" />
      <geometry>
        <mesh
          filename="/meshes/link_right_leg2.STL" />
      </geometry>
      <material
        name="white">
        <color
          rgba="0.92941 0.92941 0.92941 1" />
      </material>
    </visual>
    <collision>
      <origin
        xyz="0 0 0"
        rpy="0 0 0" />
      <geometry>
        <mesh
          filename="/meshes/link_right_leg2.STL" />
      </geometry>
    </collision>
  </link>
  <joint
    name="joint_right_leg2"
    type="revolute">
    <origin
      xyz="-0.0264026497308134 0 -0.0500000000000003"
      rpy="0 0 0" />
    <parent
      link="link_right_leg1" />
    <child
      link="link_right_leg2" />
    <axis
      xyz="-1 0 0" />
    <limit
      lower="-0.7854"
      upper="0.7854"
      effort="0"
      velocity="0.5" />
  </joint>
  <link
    name="link_right_leg3">
    <inertial>
      <origin
        xyz="0.00716392898001013 0.0937898040393344 0.0202948830746041"
        rpy="0 0 0" />
      <mass
        value="0.0478875355190944" />
      <inertia
        ixx="0.000110037716563229"
        ixy="3.55219386354368E-15"
        ixz="-4.36273895315987E-14"
        iyy="3.16470566152114E-06"
        iyz="-2.51760314658004E-07"
        izz="0.000113129438135076" />
    </inertial>
    <visual>
      <origin
        xyz="0 0 0"
        rpy="0 0 0" />
      <geometry>
        <mesh
          filename="/meshes/link_right_leg3.STL" />
      </geometry>
      <material
        name="white">
        <color
          rgba="0.92941 0.92941 0.92941 1" />
      </material>
    </visual>
    <collision>
      <origin
        xyz="0 0 0"
        rpy="0 0 0" />
      <geometry>
        <mesh
          filename="/meshes/link_right_leg3.STL" />
      </geometry>
    </collision>
  </link>
  <joint
    name="joint_right_leg3"
    type="revolute">
    <origin
      xyz="0 -0.1528 0"
      rpy="0 0 0" />
    <parent
      link="link_right_leg2" />
    <child
      link="link_right_leg3" />
    <axis
      xyz="-1 0 0" />
    <limit
      lower="-1.5707963267949"
      upper="1.5707963267949"
      effort="0"
      velocity="0.5" />
  </joint>
  <link
    name="link_right_leg4">
    <inertial>
      <origin
        xyz="0.00528196777149128 0.00395598830684224 0.0201536939736263"
        rpy="0 0 0" />
      <mass
        value="0.163665657154949" />
      <inertia
        ixx="7.36394432021319E-05"
        ixy="5.80959354606645E-09"
        ixz="3.99415138680889E-09"
        iyy="4.17151724282631E-05"
        iyz="-1.97356577468882E-06"
        izz="5.68042104491444E-05" />
    </inertial>
    <visual>
      <origin
        xyz="0.007 0.02 -0.007"
        rpy="0 -1.5707963267949 3.1415926535898" />
      <geometry>
        <mesh
          filename="/meshes/link_right_leg4.STL" />
      </geometry>
      <material
        name="gray">
        <color
          rgba="0.69804 0.69804 0.69804 1" />
      </material>
    </visual>
    <collision>
      <origin
        xyz="0.007 0.02 -0.007"
        rpy="0 -1.5707963267949 3.1415926535898" />
      <geometry>
        <mesh
          filename="/meshes/link_right_leg4.STL" />
      </geometry>
    </collision>
  </link>
  <joint
    name="joint_right_leg4"
    type="revolute">
    <origin
      xyz="0 -0.15 0"
      rpy="0 0 0" />
    <parent
      link="link_right_leg3" />
    <child
      link="link_right_leg4" />
    <axis
      xyz="-1 0 0" />
    <limit
      lower="-1.5707963267949"
      upper="0.0873"
      effort="0"
      velocity="0.5" />
  </joint>
  <link
    name="link_right_leg5">
    <inertial>
      <origin
        xyz="0.0200901030859553 -0.0106511309708631 0.0102173879229565"
        rpy="0 0 0" />
      <mass
        value="0.159112010077529" />
      <inertia
        ixx="6.62428703577581E-05"
        ixy="-6.80480411658369E-13"
        ixz="2.89498191308497E-14"
        iyy="4.30482536979824E-05"
        iyz="-1.50080193568776E-06"
        izz="4.70304467525979E-05" />
    </inertial>
    <visual>
      <origin
        xyz="-0.02 0 0"
        rpy="3.1415926535898 0 0" />
      <geometry>
        <mesh
          filename="/meshes/link_right_leg5.STL" />
      </geometry>
      <material
        name="gray">
        <color
          rgba="0.69804 0.69804 0.69804 1" />
      </material>
    </visual>
    <collision>
      <origin
        xyz="-0.02 0 0"
        rpy="3.1415926535898 0 0" />
      <geometry>
        <mesh
          filename="/meshes/link_right_leg5.STL" />
      </geometry>
    </collision>
  </link>
  <joint
    name="joint_right_leg5"
    type="revolute">
    <origin
      xyz="0.0264026497308099 0 0.0500000000000013"
      rpy="0 0 0" />
    <parent
      link="link_right_leg4" />
    <child
      link="link_right_leg5" />
    <axis
      xyz="0 0 -1" />
    <limit
      lower="-0.1745"
      upper="0.1745"
      effort="0"
      velocity="0.5" />
  </joint>
  <link
    name="link_right_feet">
    <inertial>
      <!--<origin
        xyz="2.43946816336979E-05 0.00146472823720219 0.0392652004696027"
        rpy="0 0 0" />
      <mass
        value="0.0880910671802323" />
      <inertia
        ixx="7.35993052463541E-05"
        ixy="-3.52475680147539E-11"
        ixz="3.58311623732237E-08"
        iyy="0.000286783371022584"
        iyz="6.59963258469426E-08"
        izz="0.000213316320947475" />
    </inertial>
    <visual>
      <origin
        xyz="0 0 0"
        rpy="0 0 0" />
      <geometry>
        <mesh
          filename="/meshes/link_right_feet.STL" />-->
      <origin
        xyz="-0.0176569140875253 0.178845198055025 -0.231152354370091"
        rpy="0 0 0" />
      <mass
        value="0.0954928920229025" />
      <inertia
        ixx="7.36923439922217E-05"
        ixy="-4.92591698921289E-14"
        ixz="-3.58313281195478E-08"
        iyy="0.000286832611443866"
        iyz="2.67550255632877E-14"
        izz="0.000213409300617753" />
    </inertial>
    <visual>
      <origin
        xyz="-0.022 0.18 0.27"
        rpy="1.5707963267949 3.1415926535898 0" />
      <geometry>
        <mesh
          filename="/meshes/right_feet.STL" />
      </geometry>
      <material
        name="white">
        <color
          rgba="0.92941 0.92941 0.92941 1" />
      </material>
    </visual>
    <collision>
      <origin
        xyz="-0.022 0.18 0.27"
        rpy="1.5707963267949 3.1415926535898 0" />
      <geometry>
        <mesh
          filename="/meshes/right_feet.STL" />
      </geometry>
    </collision>
    <contact>
        <!--<stiffness value="10000" />-->
	<!--zuni
        <damping value="10000" />-->
        <lateral_friction value="0.6" />
        <!--<spinning_friction value="1" />
        <rolling_friction value="1" />-->
    </contact>
  </link>
  <joint
    name="joint_right_feet"
    type="fixed">
    <origin
      xyz="-0.0200901030776536 -0.0300000000000004 -0.0589999999999928"
      rpy="1.5707963267949 -1.5707963267949 1.5707963267949" />
    <parent
      link="link_right_leg5" />
    <child
      link="link_right_feet" />
    <axis
      xyz="0 0.000898310812539769 -0.99999959651876" />
    <limit
      lower="0"
      upper="0"
      effort="0"
      velocity="0.5" />
  </joint>
  <link
    name="link_left_leg">
    <inertial>
      <origin
        xyz="-0.0200840979076337 0.00211519901297871 0.0679353577417088"
        rpy="0 0 0" />
      <mass
        value="0.189398368135878" />
      <inertia
        ixx="7.4047573208751E-05"
        ixy="-3.9292016116271E-09"
        ixz="1.80590606727013E-06"
        iyy="7.87337679439145E-05"
        iyz="3.20348680491164E-08"
        izz="5.73837775182643E-05" />
    </inertial>
    <visual>
      <origin
        xyz="-0.18 -0.395 -0.035"
        rpy="-1.5707963267949 0 0" />
      <geometry>
        <mesh
          filename="/meshes/link_left_leg.STL" />
      </geometry>
      <material
        name="darkgray">
        <color
          rgba="0.59216 0.61961 0.65098 1" />
      </material>
    </visual>
    <collision>
      <origin
        xyz="-0.18 -0.395 -0.035"
        rpy="-1.5707963267949 0 0" />
      <geometry>
        <mesh
          filename="/meshes/link_left_leg.STL" />
      </geometry>
    </collision>
  </link>
  <joint
    name="joint_left_leg"
    type="revolute">
    <origin
      xyz="0.0703079461355451 -0.0345999999999925 0.3943"
      rpy="1.5707963267949 0 0" />
    <parent
      link="robot" />
    <child
      link="link_left_leg" />
    <axis
      xyz="0 1 0" />
    <limit
      lower="-0.0873"
      upper="0.0873"
      effort="0"
      velocity="0.5" />
  </joint>
  <link
    name="link_left_leg1">
    <inertial>
      <origin
        xyz="-0.0201001030678574 -0.0164004141656287 0.00262053170527025"
        rpy="0 0 0" />
      <mass
        value="0.134775732173006" />
      <inertia
        ixx="5.19579790757104E-05"
        ixy="-6.80480429282997E-13"
        ixz="2.89497958536115E-14"
        iyy="2.9276561310441E-05"
        iyz="-1.49805771284266E-06"
        izz="4.32142876668395E-05" />
    </inertial>
    <visual>
      <origin
        xyz="0.025 -0.01 -0.017"
        rpy="1.5707963267949 3.1415926535898 0" />
      <geometry>
        <mesh
          filename="/meshes/link_left_leg1.STL" />
      </geometry>
      <material
        name="gray">
        <color
          rgba="0.69804 0.69804 0.69804 1" />
      </material>
    </visual>
    <collision>
      <origin
        xyz="0.025 -0.01 -0.017"
        rpy="1.5707963267949 3.1415926535898 0" />
      <geometry>
        <mesh
          filename="/meshes/link_left_leg1.STL" />
      </geometry>
    </collision>
  </link>
  <joint
    name="joint_left_leg1"
    type="revolute">
    <origin
      xyz="0 -0.0584999999999982 0.0499999999999998"
      rpy="0 0 0" />
    <parent
      link="link_left_leg" />
    <child
      link="link_left_leg1" />
    <axis
      xyz="0 0 -1" />
    <limit
      lower="-0.110"
      upper="0.436"
      effort="0"
      velocity="0.5" />
  </joint>
  <link
    name="link_left_leg2">
    <inertial>
      <origin
        xyz="0.00716113241658947 0.101913809829755 0.0200942165732326"
        rpy="0 0 0" />
      <mass
        value="0.190813095388896" />
      <inertia
        ixx="0.000108331753900892"
        ixy="2.79257127308398E-09"
        ixz="3.92920161180696E-09"
        iyy="4.21436661659493E-05"
        iyz="1.80590606727008E-06"
        izz="9.63817945941757E-05" />
    </inertial>
    <visual>
      <origin
        xyz="0 0 0"
        rpy="0 0 0" />
      <geometry>
        <mesh
          filename="/meshes/link_left_leg2.STL" />
      </geometry>
      <material
        name="white">
        <color
          rgba="0.92941 0.92941 0.92941 1" />
      </material>
    </visual>
    <collision>
      <origin
        xyz="0 0 0"
        rpy="0 0 0" />
      <geometry>
        <mesh
          filename="/meshes/link_left_leg2.STL" />
      </geometry>
    </collision>
  </link>
  <joint
    name="joint_left_leg2"
    type="revolute">
    <origin
      xyz="-0.0264026497308068 0 -0.0501799999999998"
      rpy="0 0 0" />
    <parent
      link="link_left_leg1" />
    <child
      link="link_left_leg2" />
    <axis
      xyz="-1 0 0" />
    <limit
      lower="-0.7854"
      upper="0.7854"
      effort="0"
      velocity="0.5" />
  </joint>
  <link
    name="link_left_leg3">
    <inertial>
      <origin
        xyz="0.00716392926639736 0.0938360222784199 -0.0201201030776547"
        rpy="0 0 0" />
      <mass
        value="0.0478875355190944" />
      <inertia
        ixx="0.000110037716563229"
        ixy="4.86050943844745E-19"
        ixz="-3.53726272211925E-20"
        iyy="3.16412926832323E-06"
        iyz="-2.45063186019447E-20"
        izz="0.000113130014528274" />
    </inertial>
    <visual>
      <origin
        xyz="0 0 0"
        rpy="0 0 0" />
      <geometry>
        <mesh
          filename="/meshes/link_left_leg3.STL" />
      </geometry>
      <material
        name="white">
        <color
          rgba="0.92941 0.92941 0.92941 1" />
      </material>
    </visual>
    <collision>
      <origin
        xyz="0 0 0"
        rpy="0 0 0" />
      <geometry>
        <mesh
          filename="/meshes/link_left_leg3.STL" />
      </geometry>
    </collision>
  </link>
  <joint
    name="joint_left_leg3"
    type="revolute">
    <origin
      xyz="1.00000000001488E-05 -0.1528 0"
      rpy="0 0 0" />
    <parent
      link="link_left_leg2" />
    <child
      link="link_left_leg3" />
    <axis
      xyz="-1 0 0" />
    <limit
      lower="-1.5707963267949"
      upper="1.5707963267949"
      effort="0"
      velocity="0.5" />
  </joint>
  <link
    name="link_left_leg4">
    <inertial>
      <origin
        xyz="0.00905071070916109 0.00417904687728667 -0.0200915814578084"
        rpy="0 0 0" />
      <mass
        value="0.163665657154949" />
      <inertia
        ixx="7.3639443202291E-05"
        ixy="-1.14385913650905E-08"
        ixz="3.92920161188149E-09"
        iyy="4.16732935950244E-05"
        iyz="-1.80590606727018E-06"
        izz="5.68460892822241E-05" />
    </inertial>
    <visual>
      <origin
        xyz="0.007 0.02 -0.007"
        rpy="0 -1.5707963267949 3.1415926535898" />
      <geometry>
        <mesh
          filename="/meshes/link_left_leg4.STL" />
      </geometry>
      <material
        name="gray">
        <color
          rgba="0.69804 0.69804 0.69804 1" />
      </material>
    </visual>
    <collision>
      <origin
        xyz="0.007 0.02 -0.007"
        rpy="0 -1.5707963267949 3.1415926535898" />
      <geometry>
        <mesh
          filename="/meshes/link_left_leg4.STL" />
      </geometry>
    </collision>
  </link>
  <joint
    name="joint_left_leg4"
    type="revolute">
    <origin
      xyz="0 -0.15 0"
      rpy="0 0 0" />
    <parent
      link="link_left_leg3" />
    <child
      link="link_left_leg4" />
    <axis
      xyz="-1 0 0" />
    <limit
      lower="-1.5707963267949"
      upper="0.0873"
      effort="0"
      velocity="0.5" />
  </joint>
  <link
    name="link_left_leg5">
    <inertial>
      <origin
        xyz="0.0201101030859564 -0.0106511309708628 0.0101898568143954"
        rpy="0 0 0" />
      <mass
        value="0.15911201007753" />
      <inertia
        ixx="6.62428703577582E-05"
        ixy="-6.80480377951717E-13"
        ixz="2.89499914949265E-14"
        iyy="4.30482536979825E-05"
        iyz="-1.50080193568775E-06"
        izz="4.7030446752598E-05" />
    </inertial>
    <visual>
      <origin
        xyz="-0.02 0 0"
        rpy="3.1415926535898 0 0" />
      <geometry>
        <mesh
          filename="/meshes/link_left_leg5.STL" />
      </geometry>
      <material
        name="gray">
        <color
          rgba="0.69804 0.69804 0.69804 1" />
      </material>
    </visual>
    <collision>
      <origin
        xyz="-0.02 0 0"
        rpy="3.1415926535898 0 0" />
      <geometry>
        <mesh
          filename="/meshes/link_left_leg5.STL" />
      </geometry>
    </collision>
  </link>
  <joint
    name="joint_left_leg5"
    type="revolute">
    <origin
      xyz="0.0264026497308091 0 0.0500000000000007"
      rpy="0 0 0" />
    <parent
      link="link_left_leg4" />
    <child
      link="link_left_leg5" />
    <axis
      xyz="0 0 -1" />
    <limit
      lower="-0.1745"
      upper="0.1745"
      effort="0"
      velocity="0.5" />
  </joint>
  <link
    name="link_left_feet">
    <inertial>
      <origin
        xyz="-0.0174086021187205 0.178855492188866 -0.269452948115134"
        rpy="0 0 0" />
      <mass
        value="0.0954928920229024" />
      <inertia
        ixx="7.36923439922216E-05"
        ixy="-4.92591846707898E-14"
        ixz="3.58310310392485E-08"
        iyy="0.000286832611443865"
        iyz="2.67550254285812E-14"
        izz="0.000213409300617753" />
    </inertial>
    <visual>
      <origin
        xyz="-0.02 -0.18 -0.23"
        rpy="-1.5707963267949 3.1415926535898 0" />
      <geometry>
        <mesh
          filename="/meshes/left_feet.STL" />
      <!--<origin
        xyz="2.43947031643502E-05 -0.00150000000000008 0.000936337309690477"
        rpy="0 0 0" />
      <mass
        value="0.0880910671802324" />
      <inertia
        ixx="7.35993052463541E-05"
        ixy="1.74492769592092E-18"
        ixz="-3.58311795792948E-08"
        iyy="0.000286783430307822"
        iyz="-4.46363225756036E-20"
        izz="0.000213316261662238" />
    </inertial>
    <visual>
      <origin
        xyz="0 0 0"
        rpy="0 0 0" />
      <geometry>
        <mesh
          filename="/meshes/link_left_feet.STL" />-->
      </geometry>
      <material
        name="white">
        <color
          rgba="0.92941 0.92941 0.92941 1" />
      </material>
    </visual>
    <collision>
      <origin
        xyz="-0.02 -0.18 -0.23"
        rpy="-1.5707963267949 3.1415926535898 0" />
      <geometry>
        <mesh
          filename="/meshes/left_feet.STL" />
      </geometry>
    </collision>
    <contact>
        <!--<stiffness value="10000" />-->
        <!--zuni
        <damping value="10000" />-->
        <lateral_friction value="0.6" />
        <!--<spinning_friction value="1" />
        <rolling_friction value="1" />-->
    </contact>
  </link>
  <joint
    name="joint_left_feet"
    type="fixed">
    <origin
      xyz="0.0201101030776549 -0.0330000000000014 -0.0588199999999928"
      rpy="0 -1.5707963267949 0" />
    <parent
      link="link_left_leg5" />
    <child
      link="link_left_feet" />
    <axis
      xyz="0 0 1" />
    <limit
      lower="0"
      upper="0"
      effort="0"
      velocity="0.5" />
  </joint>

  <transmission name="head_trans">
    <type>transmission_interface/SimpleTransmission</type>
    <joint name="joint_head" >
      <hardwareInterface>hardware_interface/PositionJointInterface</hardwareInterface>
    </joint>
    <actuator name="head_motor">
      <hardwareInterface>hardware_interface/PositionJointInterface</hardwareInterface>
      <mechanicalReduction>1</mechanicalReduction>
    </actuator>
  </transmission>

  <transmission name="camera_trans">
    <type>transmission_interface/SimpleTransmission</type>
    <joint name="joint_camera" >
      <hardwareInterface>hardware_interface/PositionJointInterface</hardwareInterface>
    </joint>
    <actuator name="camera_motor">
      <hardwareInterface>hardware_interface/PositionJointInterface</hardwareInterface>
      <mechanicalReduction>1</mechanicalReduction>
    </actuator>
  </transmission>

  <transmission name="right_arm_trans">
    <type>transmission_interface/SimpleTransmission</type>
    <joint name="joint_right_arm" >
      <hardwareInterface>hardware_interface/PositionJointInterface</hardwareInterface>
    </joint>
    <actuator name="right_arm_motor">
      <hardwareInterface>hardware_interface/PositionJointInterface</hardwareInterface>
      <mechanicalReduction>1</mechanicalReduction>
    </actuator>
  </transmission>

  <transmission name="right_elbow_trans">
    <type>transmission_interface/SimpleTransmission</type>
    <joint name="joint_right_elbow" >
      <hardwareInterface>hardware_interface/PositionJointInterface</hardwareInterface>
    </joint>
    <actuator name="right_elbow_motor">
      <hardwareInterface>hardware_interface/PositionJointInterface</hardwareInterface>
      <mechanicalReduction>1</mechanicalReduction>
    </actuator>
  </transmission>

  <transmission name="left_arm_trans">
    <type>transmission_interface/SimpleTransmission</type>
    <joint name="joint_left_arm" >
      <hardwareInterface>hardware_interface/PositionJointInterface</hardwareInterface>
    </joint>
    <actuator name="left_arm_motor">
      <hardwareInterface>hardware_interface/PositionJointInterface</hardwareInterface>
      <mechanicalReduction>1</mechanicalReduction>
    </actuator>
  </transmission>

  <transmission name="left_elbow_trans">
    <type>transmission_interface/SimpleTransmission</type>
    <joint name="joint_left_elbow" >
      <hardwareInterface>hardware_interface/PositionJointInterface</hardwareInterface>
    </joint>
    <actuator name="left_elbow_motor">
      <hardwareInterface>hardware_interface/PositionJointInterface</hardwareInterface>
      <mechanicalReduction>1</mechanicalReduction>
    </actuator>
  </transmission>

  <transmission name="right_leg_trans">
    <type>transmission_interface/SimpleTransmission</type>
    <joint name="joint_right_leg" >
      <hardwareInterface>hardware_interface/PositionJointInterface</hardwareInterface>
    </joint>
    <actuator name="right_leg_motor">
      <hardwareInterface>hardware_interface/PositionJointInterface</hardwareInterface>
      <mechanicalReduction>1</mechanicalReduction>
    </actuator>
  </transmission>

  <transmission name="right_leg1_trans">
    <type>transmission_interface/SimpleTransmission</type>
    <joint name="joint_right_leg1" >
      <hardwareInterface>hardware_interface/PositionJointInterface</hardwareInterface>
    </joint>
    <actuator name="right_leg1_motor">
      <hardwareInterface>hardware_interface/PositionJointInterface</hardwareInterface>
      <mechanicalReduction>1</mechanicalReduction>
    </actuator>
  </transmission>

  <transmission name="right_leg2_trans">
    <type>transmission_interface/SimpleTransmission</type>
    <joint name="joint_right_leg2" >
      <hardwareInterface>hardware_interface/PositionJointInterface</hardwareInterface>
    </joint>
    <actuator name="right_leg2_motor">
      <hardwareInterface>hardware_interface/PositionJointInterface</hardwareInterface>
      <mechanicalReduction>1</mechanicalReduction>
    </actuator>
  </transmission>

  <transmission name="right_leg3_trans">
    <type>transmission_interface/SimpleTransmission</type>
    <joint name="joint_right_leg3" >
      <hardwareInterface>hardware_interface/PositionJointInterface</hardwareInterface>
    </joint>
    <actuator name="right_leg3_motor">
      <hardwareInterface>hardware_interface/PositionJointInterface</hardwareInterface>
      <mechanicalReduction>1</mechanicalReduction>
    </actuator>
  </transmission>

  <transmission name="right_leg4_trans">
    <type>transmission_interface/SimpleTransmission</type>
    <joint name="joint_right_leg4" >
      <hardwareInterface>hardware_interface/PositionJointInterface</hardwareInterface>
    </joint>
    <actuator name="right_leg4_motor">
      <hardwareInterface>hardware_interface/PositionJointInterface</hardwareInterface>
      <mechanicalReduction>1</mechanicalReduction>
    </actuator>
  </transmission>

  <transmission name="right_leg5_trans">
    <type>transmission_interface/SimpleTransmission</type>
    <joint name="joint_right_leg5" >
      <hardwareInterface>hardware_interface/PositionJointInterface</hardwareInterface>
    </joint>
    <actuator name="right_leg5_motor">
      <hardwareInterface>hardware_interface/PositionJointInterface</hardwareInterface>
      <mechanicalReduction>1</mechanicalReduction>
    </actuator>
  </transmission>

  <transmission name="left_leg_trans">
    <type>transmission_interface/SimpleTransmission</type>
    <joint name="joint_left_leg" >
      <hardwareInterface>hardware_interface/PositionJointInterface</hardwareInterface>
    </joint>
    <actuator name="left_leg_motor">
      <hardwareInterface>hardware_interface/PositionJointInterface</hardwareInterface>
      <mechanicalReduction>1</mechanicalReduction>
    </actuator>
  </transmission>

  <transmission name="left_leg1_trans">
    <type>transmission_interface/SimpleTransmission</type>
    <joint name="joint_left_leg1" >
      <hardwareInterface>hardware_interface/PositionJointInterface</hardwareInterface>
    </joint>
    <actuator name="left_leg1_motor">
      <hardwareInterface>hardware_interface/PositionJointInterface</hardwareInterface>
      <mechanicalReduction>1</mechanicalReduction>
    </actuator>
  </transmission>

  <transmission name="left_leg2_trans">
    <type>transmission_interface/SimpleTransmission</type>
    <joint name="joint_left_leg2" >
      <hardwareInterface>hardware_interface/PositionJointInterface</hardwareInterface>
    </joint>
    <actuator name="left_leg2_motor">
      <hardwareInterface>hardware_interface/PositionJointInterface</hardwareInterface>
      <mechanicalReduction>1</mechanicalReduction>
    </actuator>
  </transmission>

  <transmission name="left_leg3_trans">
    <type>transmission_interface/SimpleTransmission</type>
    <joint name="joint_left_leg3" >
      <hardwareInterface>hardware_interface/PositionJointInterface</hardwareInterface>
    </joint>
    <actuator name="left_leg3_motor">
      <hardwareInterface>hardware_interface/PositionJointInterface</hardwareInterface>
      <mechanicalReduction>1</mechanicalReduction>
    </actuator>
  </transmission>

  <transmission name="left_leg4_trans">
    <type>transmission_interface/SimpleTransmission</type>
    <joint name="joint_left_leg4" >
      <hardwareInterface>hardware_interface/PositionJointInterface</hardwareInterface>
    </joint>
    <actuator name="left_leg4_motor">
      <hardwareInterface>hardware_interface/PositionJointInterface</hardwareInterface>
      <mechanicalReduction>1</mechanicalReduction>
    </actuator>
  </transmission>

  <transmission name="left_leg5_trans">
    <type>transmission_interface/SimpleTransmission</type>
    <joint name="joint_left_leg5" >
      <hardwareInterface>hardware_interface/PositionJointInterface</hardwareInterface>
    </joint>
    <actuator name="left_leg5_motor">
      <hardwareInterface>hardware_interface/PositionJointInterface</hardwareInterface>
      <mechanicalReduction>1</mechanicalReduction>
    </actuator>
  </transmission>

</robot>
